Workbook

Sheet Cover
A1: Financial Model
B3: Company
B5: Industry
B7: Date
B9: Analyst
B11: FX Rate
B13: Currency

Sheet Key Assumptions
A1: Key Assumptions | L1: Scenario: | M1: Base
A2: Scenario Assumptions | D2: Historical | G2: Forecast
D3: FY2023 | E3: FY2024 | F3: FY2025 | G3: FY2026E | H3: FY2027E | I3: FY2028E | J3: FY2029E | K3: FY2030E | L3: FY2031E | M3: FY2032E
A4: Rev Growth Override | D4: 0.3 | E4: 0.4 | F4: 0.2
A5: Gross Margin Adj | D5: 0 | E5: 0.02 | F5: -0.03
A6: SG&A % of Rev | D6: 0.15 | E6: 0.13 | F6: 0.18
A7: Exit Multiple | D7: 12 | E7: 15 | F7: 9
A9: Active Values → | B9: Rev Growth Override | D9: =INDEX(D3:F3,MATCH($C$1,{"Base","Upside","Downside"},0))
B10: Gross Margin Adj | D10: =INDEX(D4:F4,MATCH($C$1,{"Base","Upside","Downside"},0))
B11: SG&A % of Rev | D11: =INDEX(D5:F5,MATCH($C$1,{"Base","Upside","Downside"},0))
B12: Exit Multiple | D12: =INDEX(D6:F6,MATCH($C$1,{"Base","Upside","Downside"},0))
A14: REVENUE DRIVERS
A15: Segment A
A16: Volume
A17: Price
A18: Utilization %
A19: Revenue | D19: =D15*D16*D17 | E19: =E15*E16*E17 | F19: =F15*F16*F17 | G19: =G15*G16*G17 | H19: =H15*H16*H17 | I19: =I15*I16*I17 | J19: =J15*J16*J17 | K19: =K15*K16*K17 | ... M19: =M15*M16*M17
A20: Growth % | E20: =IF(D18=0,"",E18/D18-1) | F20: =IF(E18=0,"",F18/E18-1) | G20: =IF(F18=0,"",G18/F18-1) | H20: =IF(G18=0,"",H18/G18-1) | I20: =IF(H18=0,"",I18/H18-1) | J20: =IF(I18=0,"",J18/I18-1) | K20: =IF(J18=0,"",K18/J18-1) | L20: =IF(K18=0,"",L18/K18-1) | M20: =IF(L18=0,"",M18/L18-1)
A22: Segment B
A23: Volume
A24: Price
A25: Utilization %
A26: Revenue | D26: =D22*D23*D24 | E26: =E22*E23*E24 | F26: =F22*F23*F24 | G26: =G22*G23*G24 | H26: =H22*H23*H24 | I26: =I22*I23*I24 | J26: =J22*J23*J24 | K26: =K22*K23*K24 | ... M26: =M22*M23*M24
A27: Growth % | E27: =IF(D25=0,"",E25/D25-1) | F27: =IF(E25=0,"",F25/E25-1) | G27: =IF(F25=0,"",G25/F25-1) | H27: =IF(G25=0,"",H25/G25-1) | I27: =IF(H25=0,"",I25/H25-1) | J27: =IF(I25=0,"",J25/I25-1) | K27: =IF(J25=0,"",K25/J25-1) | L27: =IF(K25=0,"",L25/K25-1) | M27: =IF(L25=0,"",M25/L25-1)
A29: Segment C
A30: Volume
A31: Price
A32: Utilization %
A33: Revenue | D33: =D29*D30*D31 | E33: =E29*E30*E31 | F33: =F29*F30*F31 | G33: =G29*G30*G31 | H33: =H29*H30*H31 | I33: =I29*I30*I31 | J33: =J29*J30*J31 | K33: =K29*K30*K31 | ... M33: =M29*M30*M31
A34: Growth % | E34: =IF(D32=0,"",E32/D32-1) | F34: =IF(E32=0,"",F32/E32-1) | G34: =IF(F32=0,"",G32/F32-1) | H34: =IF(G32=0,"",H32/G32-1) | I34: =IF(H32=0,"",I32/H32-1) | J34: =IF(I32=0,"",J32/I32-1) | K34: =IF(J32=0,"",K32/J32-1) | L34: =IF(K32=0,"",L32/K32-1) | M34: =IF(L32=0,"",M32/L32-1)
A36: Total Revenue | D36: =D18+D25+D32 | E36: =E18+E25+E32 | F36: =F18+F25+F32 | G36: =G18+G25+G32 | H36: =H18+H25+H32 | I36: =I18+I25+I32 | J36: =J18+J25+J32 | K36: =K18+K25+K32 | ... M36: =M18+M25+M32
A38: COST OF GOODS SOLD
A39: Segment A COGS
A40: Raw Material %
A41: Labor %
A42: Overhead %
A43: D&A Allocation | D43: 0 | E43: 0 | F43: 0 | G43: 0 | H43: 0 | I43: 0 | J43: 0 | K43: 0 | L43: 0 | M43: 0
A44: COGS | D44: =D18*(D39+D40+D41)+D42 | E44: =E18*(E39+E40+E41)+E42 | F44: =F18*(F39+F40+F41)+F42 | G44: =G18*(G39+G40+G41)+G42 | H44: =H18*(H39+H40+H41)+H42 | I44: =I18*(I39+I40+I41)+I42 | J44: =J18*(J39+J40+J41)+J42 | K44: =K18*(K39+K40+K41)+K42 | ... M44: =M18*(M39+M40+M41)+M42
A45: Segment B COGS
A46: Raw Material %
...

Sheet TAM & Market
A1: TAM & Market
D2: Historical | G2: Forecast
D3: FY2023 | E3: FY2024 | F3: FY2025 | G3: FY2026E | H3: FY2027E | I3: FY2028E | J3: FY2029E | K3: FY2030E | L3: FY2031E | M3: FY2032E
A4: TOTAL ADDRESSABLE MARKET
A5: TAM Segment A
A6: TAM Segment B
A7: TAM Segment C
A8: Total TAM | D8: =D5+D6+D7 | E8: =E5+E6+E7 | F8: =F5+F6+F7 | G8: =G5+G6+G7 | H8: =H5+H6+H7 | I8: =I5+I6+I7 | J8: =J5+J6+J7 | K8: =K5+K6+K7 | ... M8: =M5+M6+M7
A9: TAM Growth % | E9: =IF(D8=0,"",E8/D8-1) | F9: =IF(E8=0,"",F8/E8-1) | G9: =IF(F8=0,"",G8/F8-1) | H9: =IF(G8=0,"",H8/G8-1) | I9: =IF(H8=0,"",I8/H8-1) | J9: =IF(I8=0,"",J8/I8-1) | K9: =IF(J8=0,"",K8/J8-1) | L9: =IF(K8=0,"",L8/K8-1) | M9: =IF(L8=0,"",M8/L8-1)
A11: SERVICEABLE MARKET
A12: Penetration % (A)
A13: SAM Segment A | D13: =D5*D12 | E13: =E5*E12 | F13: =F5*F12 | G13: =G5*G12 | H13: =H5*H12 | I13: =I5*I12 | J13: =J5*J12 | K13: =K5*K12 | ... M13: =M5*M12
A14: Penetration % (B)
A15: SAM Segment B | D15: =D6*D14 | E15: =E6*E14 | F15: =F6*F14 | G15: =G6*G14 | H15: =H6*H14 | I15: =I6*I14 | J15: =J6*J14 | K15: =K6*K14 | ... M15: =M6*M14
A16: Penetration % (C)
A17: SAM Segment C | D17: =D7*D16 | E17: =E7*E16 | F17: =F7*F16 | G17: =G7*G16 | H17: =H7*H16 | I17: =I7*I16 | J17: =J7*J16 | K17: =K7*K16 | ... M17: =M7*M16
A19: MARKET SHARE
A20: Revenue (A) | D20: ='Key Assumptions'!D18 | E20: ='Key Assumptions'!E18 | F20: ='Key Assumptions'!F18 | G20: ='Key Assumptions'!G18 | H20: ='Key Assumptions'!H18 | I20: ='Key Assumptions'!I18 | J20: ='Key Assumptions'!J18 | K20: ='Key Assumptions'!K18 | ... M20: ='Key Assumptions'!M18
A21: Market Share % (A) | D21: =IF(D5=0,"",D20/D5) | E21: =IF(E5=0,"",E20/E5) | F21: =IF(F5=0,"",F20/F5) | G21: =IF(G5=0,"",G20/G5) | H21: =IF(H5=0,"",H20/H5) | I21: =IF(I5=0,"",I20/I5) | J21: =IF(J5=0,"",J20/J5) | K21: =IF(K5=0,"",K20/K5) | ... M21: =IF(M5=0,"",M20/M5)
A22: Revenue (B) | D22: ='Key Assumptions'!D25 | E22: ='Key Assumptions'!E25 | F22: ='Key Assumptions'!F25 | G22: ='Key Assumptions'!G25 | H22: ='Key Assumptions'!H25 | I22: ='Key Assumptions'!I25 | J22: ='Key Assumptions'!J25 | K22: ='Key Assumptions'!K25 | ... M22: ='Key Assumptions'!M25
A23: Market Share % (B) | D23: =IF(D6=0,"",D22/D6) | E23: =IF(E6=0,"",E22/E6) | F23: =IF(F6=0,"",F22/F6) | G23: =IF(G6=0,"",G22/G6) | H23: =IF(H6=0,"",H22/H6) | I23: =IF(I6=0,"",I22/I6) | J23: =IF(J6=0,"",J22/J6) | K23: =IF(K6=0,"",K22/K6) | ... M23: =IF(M6=0,"",M22/M6)
A24: Revenue (C) | D24: ='Key Assumptions'!D32 | E24: ='Key Assumptions'!E32 | F24: ='Key Assumptions'!F32 | G24: ='Key Assumptions'!G32 | H24: ='Key Assumptions'!H32 | I24: ='Key Assumptions'!I32 | J24: ='Key Assumptions'!J32 | K24: ='Key Assumptions'!K32 | ... M24: ='Key Assumptions'!M32
A25: Market Share % (C) | D25: =IF(D7=0,"",D24/D7) | E25: =IF(E7=0,"",E24/E7) | F25: =IF(F7=0,"",F24/F7) | G25: =IF(G7=0,"",G24/G7) | H25: =IF(H7=0,"",H24/H7) | I25: =IF(I7=0,"",I24/I7) | J25: =IF(J7=0,"",J24/J7) | K25: =IF(K7=0,"",K24/K7) | ... M25: =IF(M7=0,"",M24/M7)
A27: CROSS-CHECK
A28: Bottom-up Revenue | D28: =D20+D22+D24 | E28: =E20+E22+E24 | F28: =F20+F22+F24 | G28: =G20+G22+G24 | H28: =H20+H22+H24 | I28: =I20+I22+I24 | J28: =J20+J22+J24 | K28: =K20+K22+K24 | ... M28: =M20+M22+M24
A29: Top-down Implied Revenue | D29: =D13+D15+D17 | E29: =E13+E15+E17 | F29: =F13+F15+F17 | G29: =G13+G15+G17 | H29: =H13+H15+H17 | I29: =I13+I15+I17 | J29: =J13+J15+J17 | K29: =K13+K15+K17 | ... M29: =M13+M15+M17
A30: Variance % | D30: =IF(D29=0,"",D28/D29-1) | E30: =IF(E29=0,"",E28/E29-1) | F30: =IF(F29=0,"",F28/F29-1) | G30: =IF(G29=0,"",G28/G29-1) | H30: =IF(H29=0,"",H28/H29-1) | I30: =IF(I29=0,"",I28/I29-1) | J30: =IF(J29=0,"",J28/J29-1) | K30: =IF(K29=0,"",K28/K29-1) | ... M30: =IF(M29=0,"",M28/M29-1)

Sheet Income Statement
A1: Income Statement
D2: Historical | G2: Forecast
D3: FY2023 | E3: FY2024 | F3: FY2025 | G3: FY2026E | H3: FY2027E | I3: FY2028E | J3: FY2029E | K3: FY2030E | L3: FY2031E | M3: FY2032E
A4: REVENUE
A5: Total Revenue | D5: ='Key Assumptions'!D35 | E5: ='Key Assumptions'!E35 | F5: ='Key Assumptions'!F35 | G5: ='Key Assumptions'!G35 | H5: ='Key Assumptions'!H35 | I5: ='Key Assumptions'!I35 | J5: ='Key Assumptions'!J35 | K5: ='Key Assumptions'!K35 | ... M5: ='Key Assumptions'!M35
A6: Segment A | D6: ='Key Assumptions'!D18 | E6: ='Key Assumptions'!E18 | F6: ='Key Assumptions'!F18 | G6: ='Key Assumptions'!G18 | H6: ='Key Assumptions'!H18 | I6: ='Key Assumptions'!I18 | J6: ='Key Assumptions'!J18 | K6: ='Key Assumptions'!K18 | ... M6: ='Key Assumptions'!M18
A7: Segment B | D7: ='Key Assumptions'!D25 | E7: ='Key Assumptions'!E25 | F7: ='Key Assumptions'!F25 | G7: ='Key Assumptions'!G25 | H7: ='Key Assumptions'!H25 | I7: ='Key Assumptions'!I25 | J7: ='Key Assumptions'!J25 | K7: ='Key Assumptions'!K25 | ... M7: ='Key Assumptions'!M25
A8: Segment C | D8: ='Key Assumptions'!D32 | E8: ='Key Assumptions'!E32 | F8: ='Key Assumptions'!F32 | G8: ='Key Assumptions'!G32 | H8: ='Key Assumptions'!H32 | I8: ='Key Assumptions'!I32 | J8: ='Key Assumptions'!J32 | K8: ='Key Assumptions'!K32 | ... M8: ='Key Assumptions'!M32
A10: COST OF GOODS SOLD
A11: Total COGS | D11: ='Key Assumptions'!D56 | E11: ='Key Assumptions'!E56 | F11: ='Key Assumptions'!F56 | G11: ='Key Assumptions'!G56 | H11: ='Key Assumptions'!H56 | I11: ='Key Assumptions'!I56 | J11: ='Key Assumptions'!J56 | K11: ='Key Assumptions'!K56 | ... M11: ='Key Assumptions'!M56
A12: Gross Profit | D12: =D5-D11 | E12: =E5-E11 | F12: =F5-F11 | G12: =G5-G11 | H12: =H5-H11 | I12: =I5-I11 | J12: =J5-J11 | K12: =K5-K11 | ... M12: =M5-M11
A13: Gross Margin % | D13: =IF(D5=0,"",D12/D5) | E13: =IF(E5=0,"",E12/E5) | F13: =IF(F5=0,"",F12/F5) | G13: =IF(G5=0,"",G12/G5) | H13: =IF(H5=0,"",H12/H5) | I13: =IF(I5=0,"",I12/I5) | J13: =IF(J5=0,"",J12/J5) | K13: =IF(K5=0,"",K12/K5) | ... M13: =IF(M5=0,"",M12/M5)
A15: OPERATING EXPENSES
A16: SG&A | D16: ='Key Assumptions'!D66 | E16: ='Key Assumptions'!E66 | F16: ='Key Assumptions'!F66 | G16: ='Key Assumptions'!G66 | H16: ='Key Assumptions'!H66 | I16: ='Key Assumptions'!I66 | J16: ='Key Assumptions'!J66 | K16: ='Key Assumptions'!K66 | ... M16: ='Key Assumptions'!M66
A17: EBIT | D17: =D12-D16 | E17: =E12-E16 | F17: =F12-F16 | G17: =G12-G16 | H17: =H12-H16 | I17: =I12-I16 | J17: =J12-J16 | K17: =K12-K16 | ... M17: =M12-M16
A18: EBIT Margin % | D18: =IF(D5=0,"",D17/D5) | E18: =IF(E5=0,"",E17/E5) | F18: =IF(F5=0,"",F17/F5) | G18: =IF(G5=0,"",G17/G5) | H18: =IF(H5=0,"",H17/H5) | I18: =IF(I5=0,"",I17/I5) | J18: =IF(J5=0,"",J17/J5) | K18: =IF(K5=0,"",K17/K5) | ... M18: =IF(M5=0,"",M17/M5)
A19: D&A | D19: 0 | E19: 0 | F19: 0 | G19: 0 | H19: 0 | I19: 0 | J19: 0 | K19: 0 | L19: 0 | M19: 0
A20: EBITDA | D20: =D17+D19 | E20: =E17+E19 | F20: =F17+F19 | G20: =G17+G19 | H20: =H17+H19 | I20: =I17+I19 | J20: =J17+J19 | K20: =K17+K19 | ... M20: =M17+M19
A21: EBITDA Margin % | D21: =IF(D5=0,"",D20/D5) | E21: =IF(E5=0,"",E20/E5) | F21: =IF(F5=0,"",F20/F5) | G21: =IF(G5=0,"",G20/G5) | H21: =IF(H5=0,"",H20/H5) | I21: =IF(I5=0,"",I20/I5) | J21: =IF(J5=0,"",J20/J5) | K21: =IF(K5=0,"",K20/K5) | ... M21: =IF(M5=0,"",M20/M5)
A23: BELOW THE LINE
A24: Interest Expense | D24: 0 | E24: 0 | F24: 0 | G24: 0 | H24: 0 | I24: 0 | J24: 0 | K24: 0 | L24: 0 | M24: 0
A25: Other Income/Expense
A26: EBT (Earnings Before Tax) | D26: =D17-D24+D25 | E26: =E17-E24+E25 | F26: =F17-F24+F25 | G26: =G17-G24+G25 | H26: =H17-H24+H25 | I26: =I17-I24+I25 | J26: =J17-J24+J25 | K26: =K17-K24+K25 | ... M26: =M17-M24+M25
A27: Income Tax | D27: =MAX(0,D26*'Key Assumptions'!D90) | E27: =MAX(0,E26*'Key Assumptions'!E90) | F27: =MAX(0,F26*'Key Assumptions'!F90) | G27: =MAX(0,G26*'Key Assumptions'!G90) | H27: =MAX(0,H26*'Key Assumptions'!H90) | I27: =MAX(0,I26*'Key Assumptions'!I90) | J27: =MAX(0,J26*'Key Assumptions'!J90) | K27: =MAX(0,K26*'Key Assumptions'!K90) | ... M27: =MAX(0,M26*'Key Assumptions'!M90)
A28: Net Income | D28: =D26-D27 | E28: =E26-E27 | F28: =F26-F27 | G28: =G26-G27 | H28: =H26-H27 | I28: =I26-I27 | J28: =J26-J27 | K28: =K26-K27 | ... M28: =M26-M27
A29: Net Margin % | D29: =IF(D5=0,"",D28/D5) | E29: =IF(E5=0,"",E28/E5) | F29: =IF(F5=0,"",F28/F5) | G29: =IF(G5=0,"",G28/G5) | H29: =IF(H5=0,"",H28/H5) | I29: =IF(I5=0,"",I28/I5) | J29: =IF(J5=0,"",J28/J5) | K29: =IF(K5=0,"",K28/K5) | ... M29: =IF(M5=0,"",M28/M5)
A32: CREDIT METRICS
A33: Leverage & Coverage Ratios
A34: EBITDA
A35: Net Debt
A36: Net Debt / EBITDA
A37: Interest Coverage (EBITDA / Interest)
A38: Debt Service Coverage
A39: Net Debt / Equity

Sheet Balance Sheet
A1: Balance Sheet
D2: Historical | G2: Forecast
D3: FY2023 | E3: FY2024 | F3: FY2025 | G3: FY2026E | H3: FY2027E | I3: FY2028E | J3: FY2029E | K3: FY2030E | L3: FY2031E | M3: FY2032E
A4: CURRENT ASSETS
A5: Cash & Equivalents | D5: 0 | E5: 0 | F5: 0 | G5: 0 | H5: 0 | I5: 0 | J5: 0 | K5: 0 | L5: 0 | M5: 0
A6: Accounts Receivable | D6: ='Income Statement'!D5/365*'Key Assumptions'!D70 | E6: ='Income Statement'!E5/365*'Key Assumptions'!E70 | F6: ='Income Statement'!F5/365*'Key Assumptions'!F70 | G6: ='Income Statement'!G5/365*'Key Assumptions'!G70 | H6: ='Income Statement'!H5/365*'Key Assumptions'!H70 | I6: ='Income Statement'!I5/365*'Key Assumptions'!I70 | J6: ='Income Statement'!J5/365*'Key Assumptions'!J70 | K6: ='Income Statement'!K5/365*'Key Assumptions'!K70 | ... M6: ='Income Statement'!M5/365*'Key Assumptions'!M70
A7: Inventory | D7: ='Income Statement'!D11/365*'Key Assumptions'!D72 | E7: ='Income Statement'!E11/365*'Key Assumptions'!E72 | F7: ='Income Statement'!F11/365*'Key Assumptions'!F72 | G7: ='Income Statement'!G11/365*'Key Assumptions'!G72 | H7: ='Income Statement'!H11/365*'Key Assumptions'!H72 | I7: ='Income Statement'!I11/365*'Key Assumptions'!I72 | J7: ='Income Statement'!J11/365*'Key Assumptions'!J72 | K7: ='Income Statement'!K11/365*'Key Assumptions'!K72 | ... M7: ='Income Statement'!M11/365*'Key Assumptions'!M72
A8: Prepaid Expenses | D8: ='Income Statement'!D5/365*'Key Assumptions'!D73 | E8: ='Income Statement'!E5/365*'Key Assumptions'!E73 | F8: ='Income Statement'!F5/365*'Key Assumptions'!F73 | G8: ='Income Statement'!G5/365*'Key Assumptions'!G73 | H8: ='Income Statement'!H5/365*'Key Assumptions'!H73 | I8: ='Income Statement'!I5/365*'Key Assumptions'!I73 | J8: ='Income Statement'!J5/365*'Key Assumptions'!J73 | K8: ='Income Statement'!K5/365*'Key Assumptions'!K73 | ... M8: ='Income Statement'!M5/365*'Key Assumptions'!M73
A9: Other Current Assets | D9: ='Income Statement'!D5/365*'Key Assumptions'!D74 | E9: ='Income Statement'!E5/365*'Key Assumptions'!E74 | F9: ='Income Statement'!F5/365*'Key Assumptions'!F74 | G9: ='Income Statement'!G5/365*'Key Assumptions'!G74 | H9: ='Income Statement'!H5/365*'Key Assumptions'!H74 | I9: ='Income Statement'!I5/365*'Key Assumptions'!I74 | J9: ='Income Statement'!J5/365*'Key Assumptions'!J74 | K9: ='Income Statement'!K5/365*'Key Assumptions'!K74 | ... M9: ='Income Statement'!M5/365*'Key Assumptions'!M74
A10: Total Current Assets | D10: =D5+D6+D7+D8+D9 | E10: =E5+E6+E7+E8+E9 | F10: =F5+F6+F7+F8+F9 | G10: =G5+G6+G7+G8+G9 | H10: =H5+H6+H7+H8+H9 | I10: =I5+I6+I7+I8+I9 | J10: =J5+J6+J7+J8+J9 | K10: =K5+K6+K7+K8+K9 | ... M10: =M5+M6+M7+M8+M9
A12: NON-CURRENT ASSETS
A13: PP&E, net | D13: 0 | E13: 0 | F13: 0 | G13: 0 | H13: 0 | I13: 0 | J13: 0 | K13: 0 | L13: 0 | M13: 0
A14: Intangible Assets
A15: LT Investments
A16: Other Non-Current Assets
A17: Total Non-Current Assets | D17: =D13+D14+D15+D16 | E17: =E13+E14+E15+E16 | F17: =F13+F14+F15+F16 | G17: =G13+G14+G15+G16 | H17: =H13+H14+H15+H16 | I17: =I13+I14+I15+I16 | J17: =J13+J14+J15+J16 | K17: =K13+K14+K15+K16 | ... M17: =M13+M14+M15+M16
A18: Total Assets | D18: =D10+D17 | E18: =E10+E17 | F18: =F10+F17 | G18: =G10+G17 | H18: =H10+H17 | I18: =I10+I17 | J18: =J10+J17 | K18: =K10+K17 | ... M18: =M10+M17
A20: CURRENT LIABILITIES
A21: Accounts Payable | D21: ='Income Statement'!D11/365*'Key Assumptions'!D71 | E21: ='Income Statement'!E11/365*'Key Assumptions'!E71 | F21: ='Income Statement'!F11/365*'Key Assumptions'!F71 | G21: ='Income Statement'!G11/365*'Key Assumptions'!G71 | H21: ='Income Statement'!H11/365*'Key Assumptions'!H71 | I21: ='Income Statement'!I11/365*'Key Assumptions'!I71 | J21: ='Income Statement'!J11/365*'Key Assumptions'!J71 | K21: ='Income Statement'!K11/365*'Key Assumptions'!K71 | ... M21: ='Income Statement'!M11/365*'Key Assumptions'!M71
A22: Short-Term Debt | D22: 0 | E22: 0 | F22: 0 | G22: 0 | H22: 0 | I22: 0 | J22: 0 | K22: 0 | L22: 0 | M22: 0
A23: Tax Payable
A24: Accrued Expenses
A25: Other Current Liabilities | D25: ='Income Statement'!D11/365*'Key Assumptions'!D75 | E25: ='Income Statement'!E11/365*'Key Assumptions'!E75 | F25: ='Income Statement'!F11/365*'Key Assumptions'!F75 | G25: ='Income Statement'!G11/365*'Key Assumptions'!G75 | H25: ='Income Statement'!H11/365*'Key Assumptions'!H75 | I25: ='Income Statement'!I11/365*'Key Assumptions'!I75 | J25: ='Income Statement'!J11/365*'Key Assumptions'!J75 | K25: ='Income Statement'!K11/365*'Key Assumptions'!K75 | ... M25: ='Income Statement'!M11/365*'Key Assumptions'!M75
A26: Total Current Liabilities | D26: =D21+D22+D23+D24+D25 | E26: =E21+E22+E23+E24+E25 | F26: =F21+F22+F23+F24+F25 | G26: =G21+G22+G23+G24+G25 | H26: =H21+H22+H23+H24+H25 | I26: =I21+I22+I23+I24+I25 | J26: =J21+J22+J23+J24+J25 | K26: =K21+K22+K23+K24+K25 | ... M26: =M21+M22+M23+M24+M25
A28: NON-CURRENT LIABILITIES
A29: Long-Term Debt | D29: 0 | E29: 0 | F29: 0 | G29: 0 | H29: 0 | I29: 0 | J29: 0 | K29: 0 | L29: 0 | M29: 0
A30: Other Non-Current Liabilities
A31: Total Non-Current Liabilities | D31: =D29+D30 | E31: =E29+E30 | F31: =F29+F30 | G31: =G29+G30 | H31: =H29+H30 | I31: =I29+I30 | J31: =J29+J30 | K31: =K29+K30 | ... M31: =M29+M30
A32: Total Liabilities | D32: =D26+D31 | E32: =E26+E31 | F32: =F26+F31 | G32: =G26+G31 | H32: =H26+H31 | I32: =I26+I31 | J32: =J26+J31 | K32: =K26+K31 | ... M32: =M26+M31
A34: EQUITY
A35: Share Capital
A36: Retained Earnings | E36: =D36+'Income Statement'!E28-'Income Statement'!E28*'Key Assumptions'!E87 | F36: =E36+'Income Statement'!F28-'Income Statement'!F28*'Key Assumptions'!F87 | G36: =F36+'Income Statement'!G28-'Income Statement'!G28*'Key Assumptions'!G87 | H36: =G36+'Income Statement'!H28-'Income Statement'!H28*'Key Assumptions'!H87 | I36: =H36+'Income Statement'!I28-'Income Statement'!I28*'Key Assumptions'!I87 | J36: =I36+'Income Statement'!J28-'Income Statement'!J28*'Key Assumptions'!J87 | K36: =J36+'Income Statement'!K28-'Income Statement'!K28*'Key Assumptions'!K87 | L36: =K36+'Income Statement'!L28-'Income Statement'!L28*'Key Assumptions'!L87 | M36: =L36+'Income Statement'!M28-'Income Statement'!M28*'Key Assumptions'!M87
A37: Other Reserves
A38: Total Equity | D38: =D35+D36+D37 | E38: =E35+E36+E37 | F38: =F35+F36+F37 | G38: =G35+G36+G37 | H38: =H35+H36+H37 | I38: =I35+I36+I37 | J38: =J35+J36+J37 | K38: =K35+K36+K37 | ... M38: =M35+M36+M37
A39: Total Liabilities + Equity | D39: =D32+D38 | E39: =E32+E38 | F39: =F32+F38 | G39: =G32+G38 | H39: =H32+H38 | I39: =I32+I38 | J39: =J32+J38 | K39: =K32+K38 | ... M39: =M32+M38
A40: BS CHECK (Assets - L&E) | D40: =D18-D39 | E40: =E18-E39 | F40: =F18-F39 | G40: =G18-G39 | H40: =H18-H39 | I40: =I18-I39 | J40: =J18-J39 | K40: =K18-K39 | ... M40: =M18-M39

Sheet Cash Flow Statement
A1: Cash Flow Statement
D2: Historical | G2: Forecast
D3: FY2023 | E3: FY2024 | F3: FY2025 | G3: FY2026E | H3: FY2027E | I3: FY2028E | J3: FY2029E | K3: FY2030E | L3: FY2031E | M3: FY2032E
A4: OPERATING ACTIVITIES
A5: Net Income | D5: ='Income Statement'!D28 | E5: ='Income Statement'!E28 | F5: ='Income Statement'!F28 | G5: ='Income Statement'!G28 | H5: ='Income Statement'!H28 | I5: ='Income Statement'!I28 | J5: ='Income Statement'!J28 | K5: ='Income Statement'!K28 | ... M5: ='Income Statement'!M28
A6: Depreciation & Amortization | D6: ='Income Statement'!D19 | E6: ='Income Statement'!E19 | F6: ='Income Statement'!F19 | G6: ='Income Statement'!G19 | H6: ='Income Statement'!H19 | I6: ='Income Statement'!I19 | J6: ='Income Statement'!J19 | K6: ='Income Statement'!K19 | ... M6: ='Income Statement'!M19
A7: Change in AR | E7: =-('Balance Sheet'!E6-'Balance Sheet'!D6) | F7: =-('Balance Sheet'!F6-'Balance Sheet'!E6) | G7: =-('Balance Sheet'!G6-'Balance Sheet'!F6) | H7: =-('Balance Sheet'!H6-'Balance Sheet'!G6) | I7: =-('Balance Sheet'!I6-'Balance Sheet'!H6) | J7: =-('Balance Sheet'!J6-'Balance Sheet'!I6) | K7: =-('Balance Sheet'!K6-'Balance Sheet'!J6) | L7: =-('Balance Sheet'!L6-'Balance Sheet'!K6) | M7: =-('Balance Sheet'!M6-'Balance Sheet'!L6)
A8: Change in Inventory | E8: =-('Balance Sheet'!E7-'Balance Sheet'!D7) | F8: =-('Balance Sheet'!F7-'Balance Sheet'!E7) | G8: =-('Balance Sheet'!G7-'Balance Sheet'!F7) | H8: =-('Balance Sheet'!H7-'Balance Sheet'!G7) | I8: =-('Balance Sheet'!I7-'Balance Sheet'!H7) | J8: =-('Balance Sheet'!J7-'Balance Sheet'!I7) | K8: =-('Balance Sheet'!K7-'Balance Sheet'!J7) | L8: =-('Balance Sheet'!L7-'Balance Sheet'!K7) | M8: =-('Balance Sheet'!M7-'Balance Sheet'!L7)
A9: Change in AP | E9: ='Balance Sheet'!E21-'Balance Sheet'!D21 | F9: ='Balance Sheet'!F21-'Balance Sheet'!E21 | G9: ='Balance Sheet'!G21-'Balance Sheet'!F21 | H9: ='Balance Sheet'!H21-'Balance Sheet'!G21 | I9: ='Balance Sheet'!I21-'Balance Sheet'!H21 | J9: ='Balance Sheet'!J21-'Balance Sheet'!I21 | K9: ='Balance Sheet'!K21-'Balance Sheet'!J21 | L9: ='Balance Sheet'!L21-'Balance Sheet'!K21 | M9: ='Balance Sheet'!M21-'Balance Sheet'!L21
A10: Change in Other WC
A11: Other Adjustments
A12: Operating Cash Flow | D12: =D5+D6+D7+D8+D9+D10+D11 | E12: =E5+E6+E7+E8+E9+E10+E11 | F12: =F5+F6+F7+F8+F9+F10+F11 | G12: =G5+G6+G7+G8+G9+G10+G11 | H12: =H5+H6+H7+H8+H9+H10+H11 | I12: =I5+I6+I7+I8+I9+I10+I11 | J12: =J5+J6+J7+J8+J9+J10+J11 | K12: =K5+K6+K7+K8+K9+K10+K11 | ... M12: =M5+M6+M7+M8+M9+M10+M11
A14: INVESTING ACTIVITIES
A15: Capital Expenditures | D15: =-ABS('Key Assumptions'!D79) | E15: =-ABS('Key Assumptions'!E79) | F15: =-ABS('Key Assumptions'!F79) | G15: =-ABS('Key Assumptions'!G79) | H15: =-ABS('Key Assumptions'!H79) | I15: =-ABS('Key Assumptions'!I79) | J15: =-ABS('Key Assumptions'!J79) | K15: =-ABS('Key Assumptions'!K79) | ... M15: =-ABS('Key Assumptions'!M79)
A16: Acquisitions
A17: Other Investing
A18: Investing Cash Flow | D18: =D15+D16+D17 | E18: =E15+E16+E17 | F18: =F15+F16+F17 | G18: =G15+G16+G17 | H18: =H15+H16+H17 | I18: =I15+I16+I17 | J18: =J15+J16+J17 | K18: =K15+K16+K17 | ... M18: =M15+M16+M17
A20: FINANCING ACTIVITIES
A21: Debt Issuance
A22: Debt Repayment
A23: Equity Issuance
A24: Dividends Paid | D24: =-ABS('Income Statement'!D28*'Key Assumptions'!D87) | E24: =-ABS('Income Statement'!E28*'Key Assumptions'!E87) | F24: =-ABS('Income Statement'!F28*'Key Assumptions'!F87) | G24: =-ABS('Income Statement'!G28*'Key Assumptions'!G87) | H24: =-ABS('Income Statement'!H28*'Key Assumptions'!H87) | I24: =-ABS('Income Statement'!I28*'Key Assumptions'!I87) | J24: =-ABS('Income Statement'!J28*'Key Assumptions'!J87) | K24: =-ABS('Income Statement'!K28*'Key Assumptions'!K87) | ... M24: =-ABS('Income Statement'!M28*'Key Assumptions'!M87)
A25: Other Financing
A26: Financing Cash Flow | D26: =D21+D22+D23+D24+D25 | E26: =E21+E22+E23+E24+E25 | F26: =F21+F22+F23+F24+F25 | G26: =G21+G22+G23+G24+G25 | H26: =H21+H22+H23+H24+H25 | I26: =I21+I22+I23+I24+I25 | J26: =J21+J22+J23+J24+J25 | K26: =K21+K22+K23+K24+K25 | ... M26: =M21+M22+M23+M24+M25
A28: Net Change in Cash | D28: =D12+D18+D26 | E28: =E12+E18+E26 | F28: =F12+F18+F26 | G28: =G12+G18+G26 | H28: =H12+H18+H26 | I28: =I12+I18+I26 | J28: =J12+J18+J26 | K28: =K12+K18+K26 | ... M28: =M12+M18+M26
A29: Beginning Cash | E29: =D30 | F29: =E30 | G29: =F30 | H29: =G30 | I29: =H30 | J29: =I30 | K29: =J30 | L29: =K30 | M29: =L30
A30: Ending Cash | D30: =D29+D28 | E30: =E29+E28 | F30: =F29+F28 | G30: =G29+G28 | H30: =H29+H28 | I30: =I29+I28 | J30: =J29+J28 | K30: =K29+K28 | ... M30: =M29+M28
A32: Cash Check (CF Ending - BS Cash) | D32: =D30-'Balance Sheet'!D5 | E32: =E30-'Balance Sheet'!E5 | F32: =F30-'Balance Sheet'!F5 | G32: =G30-'Balance Sheet'!G5 | H32: =H30-'Balance Sheet'!H5 | I32: =I30-'Balance Sheet'!I5 | J32: =J30-'Balance Sheet'!J5 | K32: =K30-'Balance Sheet'!K5 | ... M32: =M30-'Balance Sheet'!M5
A34: Free Cash Flow | D34: =D12+D15 | E34: =E12+E15 | F34: =F12+F15 | G34: =G12+G15 | H34: =H12+H15 | I34: =I12+I15 | J34: =J12+J15 | K34: =K12+K15 | ... M34: =M12+M15

Sheet Debt & CapEx
A1: Debt & CapEx
D2: Historical | G2: Forecast
D3: FY2023 | E3: FY2024 | F3: FY2025 | G3: FY2026E | H3: FY2027E | I3: FY2028E | J3: FY2029E | K3: FY2030E | L3: FY2031E | M3: FY2032E
A4: DEBT SCHEDULE
A5: Debt Outstanding by Tranche
A6: Tranche 1 — Senior Secured | B6: RMBm
A7: Tranche 2 — Senior Unsecured | B7: RMBm
A8: Tranche 3 — Mezzanine | B8: RMBm
A9: Tranche 4 — Subordinated | B9: RMBm
A11: Repayment Schedule
A12: Tranche 1 Repayment
A13: Tranche 2 Repayment
A14: Tranche 3 Repayment
A15: Tranche 4 Repayment
A16: Total Repayment | D16: =SUM(D12:D15) | E16: =SUM(E12:E15) | F16: =SUM(F12:F15) | G16: =SUM(G12:G15) | H16: =SUM(H12:H15) | I16: =SUM(I12:I15) | J16: =SUM(J12:J15) | K16: =SUM(K12:K15) | ... M16: =SUM(M12:M15)
A18: Summary
A19: Total Debt Outstanding | D19: =SUM(D6:D9) | E19: =SUM(E6:E9) | F19: =SUM(F6:F9) | G19: =SUM(G6:G9) | H19: =SUM(H6:H9) | I19: =SUM(I6:I9) | J19: =SUM(J6:J9) | K19: =SUM(K6:K9) | ... M19: =SUM(M6:M9)
A20: Senior Total | D20: =D6+D7 | E20: =E6+E7 | F20: =F6+F7 | G20: =G6+G7 | H20: =H6+H7 | I20: =I6+I7 | J20: =J6+J7 | K20: =K6+K7 | ... M20: =M6+M7
A21: Mezzanine Total | D21: =D8 | E21: =E8 | F21: =F8 | G21: =G8 | H21: =H8 | I21: =I8 | J21: =J8 | K21: =K8 | ... M21: =M8
A22: Subordinated Total | D22: =D9 | E22: =E9 | F22: =F9 | G22: =G9 | H22: =H9 | I22: =I9 | J22: =J9 | K22: =K9 | ... M22: =M9
A23: ST Portion (due < 1yr)
A24: LT Portion | D24: =D19-D23 | E24: =E19-E23 | F24: =F19-F23 | G24: =G19-G23 | H24: =H19-H23 | I24: =I19-I23 | J24: =J19-J23 | K24: =K19-K23 | ... M24: =M19-M23
A26: Interest
A27: Tranche 1 Rate
A28: Tranche 2 Rate
A29: Tranche 3 Rate
A30: Tranche 4 Rate
A31: Weighted Avg Rate | D31: =IFERROR((D6*D27+D7*D28+D8*D29+D9*D30)/D19,0) | E31: =IFERROR((E6*E27+E7*E28+E8*E29+E9*E30)/E19,0) | F31: =IFERROR((F6*F27+F7*F28+F8*F29+F9*F30)/F19,0) | G31: =IFERROR((G6*G27+G7*G28+G8*G29+G9*G30)/G19,0) | H31: =IFERROR((H6*H27+H7*H28+H8*H29+H9*H30)/H19,0) | I31: =IFERROR((I6*I27+I7*I28+I8*I29+I9*I30)/I19,0) | J31: =IFERROR((J6*J27+J7*J28+J8*J29+J9*J30)/J19,0) | K31: =IFERROR((K6*K27+K7*K28+K8*K29+K9*K30)/K19,0) | ... M31: =IFERROR((M6*M27+M7*M28+M8*M29+M9*M30)/M19,0)
A32: Total Interest Expense | D32: =D6*D27+D7*D28+D8*D29+D9*D30 | E32: =E6*E27+E7*E28+E8*E29+E9*E30 | F32: =F6*F27+F7*F28+F8*F29+F9*F30 | G32: =G6*G27+G7*G28+G8*G29+G9*G30 | H32: =H6*H27+H7*H28+H8*H29+H9*H30 | I32: =I6*I27+I7*I28+I8*I29+I9*I30 | J32: =J6*J27+J7*J28+J8*J29+J9*J30 | K32: =K6*K27+K7*K28+K8*K29+K9*K30 | ... M32: =M6*M27+M7*M28+M8*M29+M9*M30
A35: CAPEX & DEPRECIATION
A36: Capital Expenditure
A37: Equipment | B37: RMBm
A38: Facilities | B38: RMBm
A39: Intangible Assets | B39: RMBm
A40: Other CapEx | B40: RMBm
A41: Total CapEx | D41: =SUM(D37:D40) | E41: =SUM(E37:E40) | F41: =SUM(F37:F40) | G41: =SUM(G37:G40) | H41: =SUM(H37:H40) | I41: =SUM(I37:I40) | J41: =SUM(J37:J40) | K41: =SUM(K37:K40) | ... M41: =SUM(M37:M40)
A42: CapEx as % of Revenue
A44: Depreciation by Asset Group
A45: Asset Group 1 — Equipment | B45: RMBm
A46: Asset Group 2 — Facilities | B46: RMBm
...

Sheet Return Analysis
A1: Return Analysis
B3: ENTRY | F3: FOLLOW-ON | J3: EXIT
A4: Pre-money Valuation | F4: Round B Pre-money | J4: Exit Year
A5: Total Round Size | F5: Round B New Capital | J5: Exit Revenue
A6: Post-money Valuation | F6: Round B Post-money | J6: Exit EBITDA
F7: Round B Dilution % | J7: Exit Net Income
A8: Cathay Investment | F8: Cathay Follow-on?
A9: Cathay Ownership % | F9: Cathay Additional Invest | J9: Exit Method | K9: P/E
J10: Exit Multiple
A11: Cap Table | F11: Pre-IPO Round
A12: Founder % | F12: Pre-money | J12: Exit EV
A13: Other Investors % | F13: New Capital | J13: Less: Net Debt
A14: ESOP % | F14: Dilution % | J14: Exit Equity Value
A15: Round Investors % | F15: IPO Dilution %
A16: Cathay % | J16: Cathay Proceeds
A17: Total Check | F17: Final Ownership %
A20: CASH FLOW & RETURNS
B21: Entry | C21: Yr 1 | D21: Yr 2 | E21: Yr 3 | F21: Yr 4 | G21: Yr 5 | H21: Yr 6 | I21: Yr 7
A22: Date
A23: Investment
A24: Follow-on
A25: Dividends
A26: Exit Proceeds
A28: Net Cash Flow
A30: IRR
A31: MOIC
A33: Fund Economics
A34: Management Fee (% p.a.)
A35: Carried Interest
A36: Hurdle Rate
... A41: MOIC: Exit NI × P/E
A42: NI ↓ / P/E → | B42: 8x | C42: 10x | D42: 12x | E42: 15x | F42: 18x
A49: IRR: Exit NI × P/E
A50: NI ↓ / P/E → | B50: 8x | C50: 10x | D50: 12x | E50: 15x | F50: 18x

Sheet DCF Valuation
A1: DCF Valuation
D2: Historical | G2: Forecast
D3: FY2023 | E3: FY2024 | F3: FY2025 | G3: FY2026E | H3: FY2027E | I3: FY2028E | J3: FY2029E | K3: FY2030E | L3: FY2031E | M3: FY2032E
A4: WACC CALCULATION
A5: Cost of Capital
A6: Risk-free Rate
A7: Equity Beta
A8: Market Risk Premium
A9: Cost of Equity (Ke) | D9: =D6+D7*D8
A10: Pre-tax Cost of Debt (Kd)
A11: Effective Tax Rate
A12: After-tax Kd | D12: =D10*(1-D11)
A13: Equity Weight (E/(D+E))
A14: Debt Weight | D14: =1-D13
A15: WACC | D15: =D13*D9+D14*D12
A18: FREE CASH FLOW
A19: EBIT | B19: RMBm
A20: Tax on EBIT | D20: =D19*$D$11 | E20: =E19*$D$11 | F20: =F19*$D$11 | G20: =G19*$D$11 | H20: =H19*$D$11 | I20: =I19*$D$11 | J20: =J19*$D$11 | K20: =K19*$D$11 | ... M20: =M19*$D$11
A21: NOPAT | D21: =D19-D20 | E21: =E19-E20 | F21: =F19-F20 | G21: =G19-G20 | H21: =H19-H20 | I21: =I19-I20 | J21: =J19-J20 | K21: =K19-K20 | ... M21: =M19-M20
A22: D&A
A23: CapEx
A24: Change in Working Capital
A25: Unlevered FCF | D25: =D21+D22+D23+D24 | E25: =E21+E22+E23+E24 | F25: =F21+F22+F23+F24 | G25: =G21+G22+G23+G24 | H25: =H21+H22+H23+H24 | I25: =I21+I22+I23+I24 | J25: =J21+J22+J23+J24 | K25: =K21+K22+K23+K24 | ... M25: =M21+M22+M23+M24
A28: TERMINAL VALUE
A29: TV Method | D29: Gordon Growth
A30: Terminal Growth Rate
A31: Exit Multiple
A32: Terminal Year FCF | D32: =M25
A33: Terminal Value | D33: =IF(D29="Gordon Growth",D32*(1+D30)/($D$15-D30),D32*D31)
A36: VALUATION SUMMARY
A37: Discount Factor | D37: =1/(1+$D$15)^1 | E37: =1/(1+$D$15)^2 | F37: =1/(1+$D$15)^3 | G37: =1/(1+$D$15)^4 | H37: =1/(1+$D$15)^5 | I37: =1/(1+$D$15)^6 | J37: =1/(1+$D$15)^7 | K37: =1/(1+$D$15)^8 | L37: =1/(1+$D$15)^9 | M37: =1/(1+$D$15)^10
A38: PV of FCF | D38: =D25*D37 | E38: =E25*E37 | F38: =F25*F37 | G38: =G25*G37 | H38: =H25*H37 | I38: =I25*I37 | J38: =J25*J37 | K38: =K25*K37 | ... M38: =M25*M37
A39: Sum of PV FCFs | D39: =SUM(D38:M38)
A40: PV of Terminal Value | D40: =D33*M37
A41: Enterprise Value | D41: =D39+D40
A42: Less: Net Debt
A43: Equity Value | D43: =D41-D42

Sheet Comps
A1: Comparable Analysis
A3: TRADING COMPARABLES
A4: Company | B4: Ticker | C4: Mkt Cap | D4: EV | E4: LTM Rev | F4: NTM Rev | G4: LTM EBITDA | H4: EV/Rev | I4: EV/EBITDA | J4: P/E | K4: Rev Gr% | L4: EBITDA Mgn
A18: Statistics
A19: Average | C19: =AVERAGE(C5:C16) | D19: =AVERAGE(D5:D16) | E19: =AVERAGE(E5:E16) | F19: =AVERAGE(F5:F16) | G19: =AVERAGE(G5:G16) | H19: =AVERAGE(H5:H16) | I19: =AVERAGE(I5:I16) | J19: =AVERAGE(J5:J16) | ... L19: =AVERAGE(L5:L16)
A20: Median | C20: =MEDIAN(C5:C16) | D20: =MEDIAN(D5:D16) | E20: =MEDIAN(E5:E16) | F20: =MEDIAN(F5:F16) | G20: =MEDIAN(G5:G16) | H20: =MEDIAN(H5:H16) | I20: =MEDIAN(I5:I16) | J20: =MEDIAN(J5:J16) | ... L20: =MEDIAN(L5:L16)
A21: High | C21: =MAX(C5:C16) | D21: =MAX(D5:D16) | E21: =MAX(E5:E16) | F21: =MAX(F5:F16) | G21: =MAX(G5:G16) | H21: =MAX(H5:H16) | I21: =MAX(I5:I16) | J21: =MAX(J5:J16) | ... L21: =MAX(L5:L16)
A22: Low | C22: =MIN(C5:C16) | D22: =MIN(D5:D16) | E22: =MIN(E5:E16) | F22: =MIN(F5:F16) | G22: =MIN(G5:G16) | H22: =MIN(H5:H16) | I22: =MIN(I5:I16) | J22: =MIN(J5:J16) | ... L22: =MIN(L5:L16)
A24: PRECEDENT TRANSACTIONS
A25: Target | B25: Acquirer | C25: Date | D25: EV (RMBm) | E25: EV/Revenue | F25: EV/EBITDA | G25: Premium % | H25: Deal Type | I25: Status
A36: VALUATION FOOTBALL FIELD
A37: Valuation Summary
B38: Method | C38: Low | D38: Mid | E38: High
A39: Trading Comps (EV/EBITDA)
A40: Precedent Transactions
A41: DCF
A42: Direct P/E
A43: Blended Equity Value

Sheet Dashboard
A1: Dashboard
B3: LFY (FY2025) | C3: CFY (FY2026E) | D3: NFY (FY2027E) | E3: Exit Year
A4: P&L SUMMARY
A5: Revenue
A6: EBITDA
A7: Net Income
A8: Gross Margin %
A9: EBITDA Margin %
A10: Net Margin %
A12: CREDIT METRICS
A13: Net Debt
A14: Net Debt / EBITDA
A15: Interest Coverage (EBITDA/Int)
A16: Debt Service Coverage
... A25: MODEL CHECKS
A26: BS Balance | B26: PASS
A27: Cash Tie-out | B27: PASS
A29: Active Scenario | B29: ='Key Assumptions'!M1

Sheet Model Check
A1: Model Integrity Check
A2: Run this checklist after populating the model to verify integrity.
A3: Check Item | B3: Status | C3: Value | D3: Expected | E3: Details
A4: BALANCE SHEET CHECKS
A5: BS Balance: Total Assets = Total L + E | B5: ='Balance Sheet'!D39 | C5: 0 | D5: 0 | E5: =IF(ABS(B5)<0.01,"PASS","FAIL")
A6: BS Balance: FY2024 | B6: ='Balance Sheet'!E39 | C6: 0 | D6: 0 | E6: =IF(ABS(B6)<0.01,"PASS","FAIL")
A7: BS Balance: FY2025 | B7: ='Balance Sheet'!F39 | C7: 0 | D7: 0 | E7: =IF(ABS(B7)<0.01,"PASS","FAIL")
A8: BS Balance: FY2026E | B8: ='Balance Sheet'!G39 | C8: 0 | D8: 0 | E8: =IF(ABS(B8)<0.01,"PASS","FAIL")
A9: BS Balance: FY2027E | B9: ='Balance Sheet'!H39 | C9: 0 | D9: 0 | E9: =IF(ABS(B9)<0.01,"PASS","FAIL")
A10: BS Balance: FY2028E | B10: ='Balance Sheet'!I39 | C10: 0 | D10: 0 | E10: =IF(ABS(B10)<0.01,"PASS","FAIL")
A11: BS Balance: FY2029E | B11: ='Balance Sheet'!J39 | C11: 0 | D11: 0 | E11: =IF(ABS(B11)<0.01,"PASS","FAIL")
A12: BS Balance: FY2030E-FY2032E | B12: Check remaining years | C12: 0 | D12: 0 | E12: All forecast years must balance
A14: CASH FLOW CHECKS
A15: Cash Tie-out: CF Ending Cash = BS Cash | B15: ='Cash Flow Statement'!D32 | C15: 0 | D15: 0 | E15: =IF(ABS(B15)<0.01,"PASS","FAIL")
A16: Cash Tie-out: FY2024 | B16: ='Cash Flow Statement'!E32 | C16: 0 | D16: 0 | E16: =IF(ABS(B16)<0.01,"PASS","FAIL")
A17: Cash Tie-out: FY2025 | B17: ='Cash Flow Statement'!F32 | C17: 0 | D17: 0 | E17: =IF(ABS(B17)<0.01,"PASS","FAIL")
A18: Cash Tie-out: FY2026E-FY2032E | B18: Check all forecast years | C18: 0 | D18: 0 | E18: All years must tie out
A19: Beginning Cash = Prior Ending Cash | B19: Verify continuity | C19: 0 | D19: 0 | E19: No breaks in cash waterfall
A21: INCOME STATEMENT CHECKS
A22: Revenue = Sum of Segments | B22: Rev Build-up Total vs IS Revenue | C22: 0 | D22: 0 | E22: Bottom-up must match IS top line
A23: COGS ≤ Revenue (Gross Margin > 0) | B23: Check all years | C23: >0% | D23: >0% | E23: Negative gross margin = red flag
A24: EBITDA = EBIT + D&A | B24: Verify formula integrity | C24: 0 | D24: 0 | E24: EBITDA decomposition must be correct
A25: Tax = EBT × Tax Rate | B25: Verify tax calc | C25: 0 | D25: 0 | E25: No tax when EBT is negative
A26: Net Income = EBT - Tax | B26: Verify bottom line | C26: 0 | D26: 0 | E26: Final NI formula check
A28: WORKING CAPITAL CHECKS
A29: AR Days reasonable (0-180) | B29: Check all forecast years | C29: 0-180 | D29: 0-180 | E29: AR days outside range = input error
A30: AP Days reasonable (0-180) | B30: Check all forecast years | C30: 0-180 | D30: 0-180 | E30: AP days outside range = input error
A31: Inventory Days reasonable (0-365) | B31: Check all forecast years | C31: 0-365 | D31: 0-365 | E31: Inventory days outside range = input error
A32: CCC = AR + Inv - AP | B32: Verify formula | C32: Positive | D32: Positive | E32: Negative CCC unusual for most industries
A33: WC change sign matches delta in accounts | B33: BS ΔAR vs CF ΔAR | C33: 0 | D33: 0 | E33: Direction must be consistent
A35: CROSS-SHEET LINKAGE CHECKS
A36: IS Revenue = Revenue Build-up Total | B36: Compare sheets | C36: 0 | D36: 0 | E36: Revenue must flow correctly
A37: IS COGS = Key Assumptions Total COGS | B37: Compare sheets | C37: 0 | D37: 0 | E37: COGS linkage
A38: IS Interest = Debt & CapEx Interest Expense | B38: Compare sheets | C38: 0 | D38: 0 | E38: Interest expense linkage
A39: BS PP&E = Debt & CapEx Net PP&E | B39: Compare sheets | C39: 0 | D39: 0 | E39: Fixed asset linkage
A40: BS ST Debt = Debt & CapEx ST Portion | B40: Compare sheets | C40: 0 | D40: 0 | E40: Debt classification
A41: BS LT Debt = Debt & CapEx LT Portion | B41: Compare sheets | C41: 0 | D41: 0 | E41: Debt classification
A42: CF CapEx = Debt & CapEx Total CapEx | B42: Compare sheets | C42: 0 | D42: 0 | E42: CapEx linkage
A43: CF D&A = Debt & CapEx Total D&A | B43: Compare sheets | C43: 0 | D43: 0 | E43: D&A linkage
A44: DCF EBIT = IS EBIT | B44: Compare sheets | C44: 0 | D44: 0 | E44: DCF input consistency
...
