Workbook

Sheet Cover
A4: Company Name
A5: Industry / Sector
A6: Date
A7: Analyst
A8: FX Rate (USD/RMB)
A9: Base Currency

Sheet Key Assumptions
A1: Key Assumptions
D3: 2021 | E3: 2022 | F3: 2023 | G3: 2024 | H3: 2025E | I3: 2026E | J3: 2027E | K3: 2028E | L3: 2029E
A5: Scenario
A6: Active Scenario | H6: Base
A7: Revenue Multiplier | B7: x
A8: Margin Adjustment | B8: bps
A10: SEGMENT A REVENUE DRIVERS
A11: Volume (units) | B11: units
A12: ASP | B12: RMB
A13: Utilization Rate | B13: %
A14: Segment A Revenue | B14: RMB mn | H14: =H11*H12*H13 | I14: =I11*I12*I13 | J14: =J11*J12*J13 | K14: =K11*K12*K13 | L14: =L11*L12*L13
A15: YoY Growth | B15: % | H15: =IF(G14=0,"",(H14/G14-1)) | I15: =IF(H14=0,"",(I14/H14-1)) | J15: =IF(I14=0,"",(J14/I14-1)) | K15: =IF(J14=0,"",(K14/J14-1)) | L15: =IF(K14=0,"",(L14/K14-1))
A16: % of Total Revenue | B16: % | H16: =IF(H34=0,"",H14/H34) | I16: =IF(I34=0,"",I14/I34) | J16: =IF(J34=0,"",J14/J34) | K16: =IF(K34=0,"",K14/K34) | L16: =IF(L34=0,"",L14/L34)
A18: SEGMENT B REVENUE DRIVERS
A19: Volume (units) | B19: units
A20: ASP | B20: RMB
A21: Utilization Rate | B21: %
A22: Segment B Revenue | B22: RMB mn | H22: =H19*H20*H21 | I22: =I19*I20*I21 | J22: =J19*J20*J21 | K22: =K19*K20*K21 | L22: =L19*L20*L21
A23: YoY Growth | B23: % | H23: =IF(G22=0,"",(H22/G22-1)) | I23: =IF(H22=0,"",(I22/H22-1)) | J23: =IF(I22=0,"",(J22/I22-1)) | K23: =IF(J22=0,"",(K22/J22-1)) | L23: =IF(K22=0,"",(L22/K22-1))
A24: % of Total Revenue | B24: % | H24: =IF(H34=0,"",H22/H34) | I24: =IF(I34=0,"",I22/I34) | J24: =IF(J34=0,"",J22/J34) | K24: =IF(K34=0,"",K22/K34) | L24: =IF(L34=0,"",L22/L34)
A26: SEGMENT C REVENUE DRIVERS
A27: Volume (units) | B27: units
A28: ASP | B28: RMB
A29: Utilization Rate | B29: %
A30: Segment C Revenue | B30: RMB mn | H30: =H27*H28*H29 | I30: =I27*I28*I29 | J30: =J27*J28*J29 | K30: =K27*K28*K29 | L30: =L27*L28*L29
A31: YoY Growth | B31: % | H31: =IF(G30=0,"",(H30/G30-1)) | I31: =IF(H30=0,"",(I30/H30-1)) | J31: =IF(I30=0,"",(J30/I30-1)) | K31: =IF(J30=0,"",(K30/J30-1)) | L31: =IF(K30=0,"",(L30/K30-1))
A32: % of Total Revenue | B32: % | H32: =IF(H34=0,"",H30/H34) | I32: =IF(I34=0,"",I30/I34) | J32: =IF(J34=0,"",J30/J34) | K32: =IF(K34=0,"",K30/K34) | L32: =IF(L34=0,"",L30/L34)
A34: Total Revenue | B34: RMB mn | H34: =H14+H22+H30 | I34: =I14+I22+I30 | J34: =J14+J22+J30 | K34: =K14+K22+K30 | L34: =L14+L22+L30
A35: Total Revenue Growth | B35: % | H35: =IF(G34=0,"",(H34/G34-1)) | I35: =IF(H34=0,"",(I34/H34-1)) | J35: =IF(I34=0,"",(J34/I34-1)) | K35: =IF(J34=0,"",(K34/J34-1)) | L35: =IF(K34=0,"",(L34/K34-1))
A37: COST ASSUMPTIONS
A38: COGS % — Segment A | B38: %
A39: COGS % — Segment B | B39: %
A40: COGS % — Segment C | B40: %
A41: Blended COGS % | B41: % | H41: =IF(H34=0,"",(H14*H38+H22*H39+H30*H40)/H34) | I41: =IF(I34=0,"",(I14*I38+I22*I39+I30*I40)/I34) | J41: =IF(J34=0,"",(J14*J38+J22*J39+J30*J40)/J34) | K41: =IF(K34=0,"",(K14*K38+K22*K39+K30*K40)/K34) | L41: =IF(L34=0,"",(L14*L38+L22*L39+L30*L40)/L34)
A42: Gross Margin | B42: % | H42: =IF(H41="","",1-H41) | I42: =IF(I41="","",1-I41) | J42: =IF(J41="","",1-J41) | K42: =IF(K41="","",1-K41) | L42: =IF(L41="","",1-L41)
A44: OPEX ASSUMPTIONS
A45: Personnel (% of Rev) | B45: %
A46: Rent (% of Rev) | B46: %
A47: Marketing (% of Rev) | B47: %
A48: R&D (% of Rev) | B48: %
...

Sheet Revenue Build-up
A1: Revenue Build-up
D3: 2021 | E3: 2022 | F3: 2023 | G3: 2024 | H3: 2025E | I3: 2026E | J3: 2027E | K3: 2028E | L3: 2029E
A5: BOTTOM-UP REVENUE BUILD
A6: Segment A | B6: RMB mn
A7: Segment B | B7: RMB mn
A8: Segment C | B8: RMB mn
A10: Total Revenue (Bottom-Up) | B10: RMB mn
A12: TOP-DOWN CROSS-CHECK
A13: Total Addressable Market | B13: RMB mn
A14: Market Penetration | B14: %
A15: Market Share | B15: %
A17: Total Revenue (Top-Down) | B17: RMB mn
A19: RECONCILIATION
A20: BU vs TD Variance | B20: %
A21: Flag (>10% = CHECK)
A23: REVENUE MIX
A24: Segment A % | B24: %
A25: Segment B % | B25: %
A26: Segment C % | B26: %
A28: YOY GROWTH
A29: Total Revenue Growth | B29: %
A30: Segment A Growth | B30: %
A31: Segment B Growth | B31: %
A32: Segment C Growth | B32: %

Sheet COGS & OpEx
A1: COGS & OpEx
D3: 2021 | E3: 2022 | F3: 2023 | G3: 2024 | H3: 2025E | I3: 2026E | J3: 2027E | K3: 2028E | L3: 2029E
A5: COST OF GOODS SOLD
A6: COGS — Segment A | B6: RMB mn | H6: ='Key Assumptions'!H14*'Key Assumptions'!H38 | I6: ='Key Assumptions'!I14*'Key Assumptions'!I38 | J6: ='Key Assumptions'!J14*'Key Assumptions'!J38 | K6: ='Key Assumptions'!K14*'Key Assumptions'!K38 | L6: ='Key Assumptions'!L14*'Key Assumptions'!L38
A7: COGS — Segment B | B7: RMB mn | H7: ='Key Assumptions'!H22*'Key Assumptions'!H39 | I7: ='Key Assumptions'!I22*'Key Assumptions'!I39 | J7: ='Key Assumptions'!J22*'Key Assumptions'!J39 | K7: ='Key Assumptions'!K22*'Key Assumptions'!K39 | L7: ='Key Assumptions'!L22*'Key Assumptions'!L39
A8: COGS — Segment C | B8: RMB mn | H8: ='Key Assumptions'!H30*'Key Assumptions'!H40 | I8: ='Key Assumptions'!I30*'Key Assumptions'!I40 | J8: ='Key Assumptions'!J30*'Key Assumptions'!J40 | K8: ='Key Assumptions'!K30*'Key Assumptions'!K40 | L8: ='Key Assumptions'!L30*'Key Assumptions'!L40
A10: Total COGS | B10: RMB mn | H10: =H6+H7+H8 | I10: =I6+I7+I8 | J10: =J6+J7+J8 | K10: =K6+K7+K8 | L10: =L6+L7+L8
A11: COGS % of Revenue | B11: % | H11: =IF('Key Assumptions'!H34=0,"",H10/'Key Assumptions'!H34) | I11: =IF('Key Assumptions'!I34=0,"",I10/'Key Assumptions'!I34) | J11: =IF('Key Assumptions'!J34=0,"",J10/'Key Assumptions'!J34) | K11: =IF('Key Assumptions'!K34=0,"",K10/'Key Assumptions'!K34) | L11: =IF('Key Assumptions'!L34=0,"",L10/'Key Assumptions'!L34)
A13: Gross Profit | B13: RMB mn | H13: ='Key Assumptions'!H34-H10 | I13: ='Key Assumptions'!I34-I10 | J13: ='Key Assumptions'!J34-J10 | K13: ='Key Assumptions'!K34-K10 | L13: ='Key Assumptions'!L34-L10
A14: Gross Margin | B14: % | H14: =IF('Key Assumptions'!H34=0,"",H13/'Key Assumptions'!H34) | I14: =IF('Key Assumptions'!I34=0,"",I13/'Key Assumptions'!I34) | J14: =IF('Key Assumptions'!J34=0,"",J13/'Key Assumptions'!J34) | K14: =IF('Key Assumptions'!K34=0,"",K13/'Key Assumptions'!K34) | L14: =IF('Key Assumptions'!L34=0,"",L13/'Key Assumptions'!L34)
A16: SG&A EXPENSES
A17: Personnel | B17: RMB mn | H17: ='Key Assumptions'!H34*'Key Assumptions'!H45 | I17: ='Key Assumptions'!I34*'Key Assumptions'!I45 | J17: ='Key Assumptions'!J34*'Key Assumptions'!J45 | K17: ='Key Assumptions'!K34*'Key Assumptions'!K45 | L17: ='Key Assumptions'!L34*'Key Assumptions'!L45
A18: Rent & Facilities | B18: RMB mn | H18: ='Key Assumptions'!H34*'Key Assumptions'!H46 | I18: ='Key Assumptions'!I34*'Key Assumptions'!I46 | J18: ='Key Assumptions'!J34*'Key Assumptions'!J46 | K18: ='Key Assumptions'!K34*'Key Assumptions'!K46 | L18: ='Key Assumptions'!L34*'Key Assumptions'!L46
A19: Marketing & Sales | B19: RMB mn | H19: ='Key Assumptions'!H34*'Key Assumptions'!H47 | I19: ='Key Assumptions'!I34*'Key Assumptions'!I47 | J19: ='Key Assumptions'!J34*'Key Assumptions'!J47 | K19: ='Key Assumptions'!K34*'Key Assumptions'!K47 | L19: ='Key Assumptions'!L34*'Key Assumptions'!L47
A20: Research & Development | B20: RMB mn | H20: ='Key Assumptions'!H34*'Key Assumptions'!H48 | I20: ='Key Assumptions'!I34*'Key Assumptions'!I48 | J20: ='Key Assumptions'!J34*'Key Assumptions'!J48 | K20: ='Key Assumptions'!K34*'Key Assumptions'!K48 | L20: ='Key Assumptions'!L34*'Key Assumptions'!L48
A21: Other Operating Expenses | B21: RMB mn | H21: ='Key Assumptions'!H34*'Key Assumptions'!H49 | I21: ='Key Assumptions'!I34*'Key Assumptions'!I49 | J21: ='Key Assumptions'!J34*'Key Assumptions'!J49 | K21: ='Key Assumptions'!K34*'Key Assumptions'!K49 | L21: ='Key Assumptions'!L34*'Key Assumptions'!L49
A23: Total SG&A | B23: RMB mn | H23: =H17+H18+H19+H20+H21 | I23: =I17+I18+I19+I20+I21 | J23: =J17+J18+J19+J20+J21 | K23: =K17+K18+K19+K20+K21 | L23: =L17+L18+L19+L20+L21
A24: SG&A % of Revenue | B24: % | H24: =IF('Key Assumptions'!H34=0,"",H23/'Key Assumptions'!H34) | I24: =IF('Key Assumptions'!I34=0,"",I23/'Key Assumptions'!I34) | J24: =IF('Key Assumptions'!J34=0,"",J23/'Key Assumptions'!J34) | K24: =IF('Key Assumptions'!K34=0,"",K23/'Key Assumptions'!K34) | L24: =IF('Key Assumptions'!L34=0,"",L23/'Key Assumptions'!L34)
A26: DEPRECIATION & AMORTIZATION
A27: Depreciation | B27: RMB mn | H27: ='Debt & CapEx'!H35 | I27: ='Debt & CapEx'!I35 | J27: ='Debt & CapEx'!J35 | K27: ='Debt & CapEx'!K35 | L27: ='Debt & CapEx'!L35
A28: Amortization | B28: RMB mn | H28: 0 | I28: 0 | J28: 0 | K28: 0 | L28: 0
A29: Total D&A | B29: RMB mn | H29: =H27+H28 | I29: =I27+I28 | J29: =J27+J28 | K29: =K27+K28 | L29: =L27+L28
A31: Total Operating Expenses | B31: RMB mn | H31: =H23+H29 | I31: =I23+I29 | J31: =J23+J29 | K31: =K23+K29 | L31: =L23+L29
A33: EBITDA BRIDGE
A34: EBITDA | B34: RMB mn | H34: =H13-H23 | I34: =I13-I23 | J34: =J13-J23 | K34: =K13-K23 | L34: =L13-L23
A35: EBITDA Margin | B35: % | H35: =IF('Key Assumptions'!H34=0,"",H34/'Key Assumptions'!H34) | I35: =IF('Key Assumptions'!I34=0,"",I34/'Key Assumptions'!I34) | J35: =IF('Key Assumptions'!J34=0,"",J34/'Key Assumptions'!J34) | K35: =IF('Key Assumptions'!K34=0,"",K34/'Key Assumptions'!K34) | L35: =IF('Key Assumptions'!L34=0,"",L34/'Key Assumptions'!L34)
A37: EBIT | B37: RMB mn | H37: =H34-H29 | I37: =I34-I29 | J37: =J34-J29 | K37: =K34-K29 | L37: =L34-L29
A38: EBIT Margin | B38: % | H38: =IF('Key Assumptions'!H34=0,"",H37/'Key Assumptions'!H34) | I38: =IF('Key Assumptions'!I34=0,"",I37/'Key Assumptions'!I34) | J38: =IF('Key Assumptions'!J34=0,"",J37/'Key Assumptions'!J34) | K38: =IF('Key Assumptions'!K34=0,"",K37/'Key Assumptions'!K34) | L38: =IF('Key Assumptions'!L34=0,"",L37/'Key Assumptions'!L34)

Sheet Income Statement
A1: Income Statement
D3: 2021 | E3: 2022 | F3: 2023 | G3: 2024 | H3: 2025E | I3: 2026E | J3: 2027E | K3: 2028E | L3: 2029E
A5: Revenue | B5: RMB mn | H5: ='Key Assumptions'!H34 | I5: ='Key Assumptions'!I34 | J5: ='Key Assumptions'!J34 | K5: ='Key Assumptions'!K34 | L5: ='Key Assumptions'!L34
A7: Cost of Goods Sold | B7: RMB mn | H7: ='COGS & OpEx'!H10 | I7: ='COGS & OpEx'!I10 | J7: ='COGS & OpEx'!J10 | K7: ='COGS & OpEx'!K10 | L7: ='COGS & OpEx'!L10
A9: Gross Profit | B9: RMB mn | H9: =H5-H7 | I9: =I5-I7 | J9: =J5-J7 | K9: =K5-K7 | L9: =L5-L7
A10: Gross Margin | B10: % | H10: =IF(H5=0,"",H9/H5) | I10: =IF(I5=0,"",I9/I5) | J10: =IF(J5=0,"",J9/J5) | K10: =IF(K5=0,"",K9/K5) | L10: =IF(L5=0,"",L9/L5)
A12: SG&A Expenses | B12: RMB mn | H12: ='COGS & OpEx'!H23 | I12: ='COGS & OpEx'!I23 | J12: ='COGS & OpEx'!J23 | K12: ='COGS & OpEx'!K23 | L12: ='COGS & OpEx'!L23
A13: Other Income / (Expense) | B13: RMB mn
A15: EBITDA | B15: RMB mn | H15: =H9-H12+H13 | I15: =I9-I12+I13 | J15: =J9-J12+J13 | K15: =K9-K12+K13 | L15: =L9-L12+L13
A16: EBITDA Margin | B16: % | H16: =IF(H5=0,"",H15/H5) | I16: =IF(I5=0,"",I15/I5) | J16: =IF(J5=0,"",J15/J5) | K16: =IF(K5=0,"",K15/K5) | L16: =IF(L5=0,"",L15/L5)
A18: Depreciation & Amortization | B18: RMB mn | H18: ='COGS & OpEx'!H29 | I18: ='COGS & OpEx'!I29 | J18: ='COGS & OpEx'!J29 | K18: ='COGS & OpEx'!K29 | L18: ='COGS & OpEx'!L29
A20: EBIT | B20: RMB mn | H20: =H15-H18 | I20: =I15-I18 | J20: =J15-J18 | K20: =K15-K18 | L20: =L15-L18
A21: EBIT Margin | B21: % | H21: =IF(H5=0,"",H20/H5) | I21: =IF(I5=0,"",I20/I5) | J21: =IF(J5=0,"",J20/J5) | K21: =IF(K5=0,"",K20/K5) | L21: =IF(L5=0,"",L20/L5)
A23: Interest Expense | B23: RMB mn | H23: ='Debt & CapEx'!H23 | I23: ='Debt & CapEx'!I23 | J23: ='Debt & CapEx'!J23 | K23: ='Debt & CapEx'!K23 | L23: ='Debt & CapEx'!L23
A24: Other Financial Items | B24: RMB mn
A26: Earnings Before Tax | B26: RMB mn | H26: =H20-H23+H24 | I26: =I20-I23+I24 | J26: =J20-J23+J24 | K26: =K20-K23+K24 | L26: =L20-L23+L24
A27: Income Tax | B27: RMB mn | H27: =IF(H26>0,H26*'Key Assumptions'!H66,0) | I27: =IF(I26>0,I26*'Key Assumptions'!I66,0) | J27: =IF(J26>0,J26*'Key Assumptions'!J66,0) | K27: =IF(K26>0,K26*'Key Assumptions'!K66,0) | L27: =IF(L26>0,L26*'Key Assumptions'!L66,0)
A28: Effective Tax Rate | B28: % | H28: =IF(H26=0,"",H27/H26) | I28: =IF(I26=0,"",I27/I26) | J28: =IF(J26=0,"",J27/J26) | K28: =IF(K26=0,"",K27/K26) | L28: =IF(L26=0,"",L27/L26)
A30: Net Income | B30: RMB mn | H30: =H26-H27 | I30: =I26-I27 | J30: =J26-J27 | K30: =K26-K27 | L30: =L26-L27
A31: Net Margin | B31: % | H31: =IF(H5=0,"",H30/H5) | I31: =IF(I5=0,"",I30/I5) | J31: =IF(J5=0,"",J30/J5) | K31: =IF(K5=0,"",K30/K5) | L31: =IF(L5=0,"",L30/L5)
A33: Shares Outstanding | B33: mn
A34: Earnings Per Share | B34: RMB

Sheet Balance Sheet
A1: Balance Sheet
D3: 2021 | E3: 2022 | F3: 2023 | G3: 2024 | H3: 2025E | I3: 2026E | J3: 2027E | K3: 2028E | L3: 2029E
A5: CURRENT ASSETS
A6: Cash & Equivalents | B6: RMB mn | H6: ='Cash Flow Statement'!H32 | I6: ='Cash Flow Statement'!I32 | J6: ='Cash Flow Statement'!J32 | K6: ='Cash Flow Statement'!K32 | L6: ='Cash Flow Statement'!L32
A7: Accounts Receivable | B7: RMB mn | H7: ='Working Capital'!H11 | I7: ='Working Capital'!I11 | J7: ='Working Capital'!J11 | K7: ='Working Capital'!K11 | L7: ='Working Capital'!L11
A8: Inventory | B8: RMB mn | H8: ='Working Capital'!H12 | I8: ='Working Capital'!I12 | J8: ='Working Capital'!J12 | K8: ='Working Capital'!K12 | L8: ='Working Capital'!L12
A9: Other Current Assets | B9: RMB mn
A11: Total Current Assets | B11: RMB mn | H11: =H6+H7+H8+H9 | I11: =I6+I7+I8+I9 | J11: =J6+J7+J8+J9 | K11: =K6+K7+K8+K9 | L11: =L6+L7+L8+L9
A13: NON-CURRENT ASSETS
A14: PP&E, Net | B14: RMB mn | H14: ='Debt & CapEx'!H36 | I14: ='Debt & CapEx'!I36 | J14: ='Debt & CapEx'!J36 | K14: ='Debt & CapEx'!K36 | L14: ='Debt & CapEx'!L36
A15: Intangibles & Goodwill | B15: RMB mn
A16: Other Non-Current Assets | B16: RMB mn
A18: Total Non-Current Assets | B18: RMB mn | H18: =H14+H15+H16 | I18: =I14+I15+I16 | J18: =J14+J15+J16 | K18: =K14+K15+K16 | L18: =L14+L15+L16
A20: TOTAL ASSETS | B20: RMB mn | H20: =H11+H18 | I20: =I11+I18 | J20: =J11+J18 | K20: =K11+K18 | L20: =L11+L18
A22: CURRENT LIABILITIES
A23: Accounts Payable | B23: RMB mn | H23: ='Working Capital'!H13 | I23: ='Working Capital'!I13 | J23: ='Working Capital'!J13 | K23: ='Working Capital'!K13 | L23: ='Working Capital'!L13
A24: Short-term Debt | B24: RMB mn
A25: Other Current Liabilities | B25: RMB mn
A27: Total Current Liabilities | B27: RMB mn | H27: =H23+H24+H25 | I27: =I23+I24+I25 | J27: =J23+J24+J25 | K27: =K23+K24+K25 | L27: =L23+L24+L25
A29: NON-CURRENT LIABILITIES
A30: Long-term Debt | B30: RMB mn | H30: ='Debt & CapEx'!H22 | I30: ='Debt & CapEx'!I22 | J30: ='Debt & CapEx'!J22 | K30: ='Debt & CapEx'!K22 | L30: ='Debt & CapEx'!L22
A31: Other Non-Current Liabilities | B31: RMB mn
A33: Total Non-Current Liabilities | B33: RMB mn | H33: =H30+H31 | I33: =I30+I31 | J33: =J30+J31 | K33: =K30+K31 | L33: =L30+L31
A35: Total Liabilities | B35: RMB mn | H35: =H27+H33 | I35: =I27+I33 | J35: =J27+J33 | K35: =K27+K33 | L35: =L27+L33
A37: EQUITY
A38: Paid-in Capital | B38: RMB mn
A39: Retained Earnings | B39: RMB mn | H39: =G39+'Income Statement'!H30-'Income Statement'!H30*'Key Assumptions'!H67 | I39: =H39+'Income Statement'!I30-'Income Statement'!I30*'Key Assumptions'!I67 | J39: =I39+'Income Statement'!J30-'Income Statement'!J30*'Key Assumptions'!J67 | K39: =J39+'Income Statement'!K30-'Income Statement'!K30*'Key Assumptions'!K67 | L39: =K39+'Income Statement'!L30-'Income Statement'!L30*'Key Assumptions'!L67
A41: Total Equity | B41: RMB mn | H41: =H38+H39 | I41: =I38+I39 | J41: =J38+J39 | K41: =K38+K39 | L41: =L38+L39
A43: TOTAL LIABILITIES + EQUITY | B43: RMB mn | H43: =H35+H41 | I43: =I35+I41 | J43: =J35+J41 | K43: =K35+K41 | L43: =L35+L41
A45: Balance Check (must = 0) | B45: RMB mn | H45: =ROUND(H20-H43,2) | I45: =ROUND(I20-I43,2) | J45: =ROUND(J20-J43,2) | K45: =ROUND(K20-K43,2) | L45: =ROUND(L20-L43,2)

Sheet Cash Flow Statement
A1: Cash Flow Statement
D3: 2021 | E3: 2022 | F3: 2023 | G3: 2024 | H3: 2025E | I3: 2026E | J3: 2027E | K3: 2028E | L3: 2029E
A5: OPERATING ACTIVITIES
A6: Net Income | B6: RMB mn | H6: ='Income Statement'!H30 | I6: ='Income Statement'!I30 | J6: ='Income Statement'!J30 | K6: ='Income Statement'!K30 | L6: ='Income Statement'!L30
A7: Depreciation & Amortization | B7: RMB mn | H7: ='COGS & OpEx'!H29 | I7: ='COGS & OpEx'!I29 | J7: ='COGS & OpEx'!J29 | K7: ='COGS & OpEx'!K29 | L7: ='COGS & OpEx'!L29
A8: Change in Accounts Receivable | B8: RMB mn | H8: =-'Working Capital'!H18 | I8: =-'Working Capital'!I18 | J8: =-'Working Capital'!J18 | K8: =-'Working Capital'!K18 | L8: =-'Working Capital'!L18
A9: Change in Inventory | B9: RMB mn | H9: =-'Working Capital'!H19 | I9: =-'Working Capital'!I19 | J9: =-'Working Capital'!J19 | K9: =-'Working Capital'!K19 | L9: =-'Working Capital'!L19
A10: Change in Accounts Payable | B10: RMB mn | H10: ='Working Capital'!H20 | I10: ='Working Capital'!I20 | J10: ='Working Capital'!J20 | K10: ='Working Capital'!K20 | L10: ='Working Capital'!L20
A11: Change in Other Working Capital | B11: RMB mn
A12: Total Change in Working Capital | B12: RMB mn | H12: =H8+H9+H10+H11 | I12: =I8+I9+I10+I11 | J12: =J8+J9+J10+J11 | K12: =K8+K9+K10+K11 | L12: =L8+L9+L10+L11
A14: Cash from Operations | B14: RMB mn | H14: =H6+H7+H12 | I14: =I6+I7+I12 | J14: =J6+J7+J12 | K14: =K6+K7+K12 | L14: =L6+L7+L12
A16: INVESTING ACTIVITIES
A17: Capital Expenditures | B17: RMB mn | H17: =-'Debt & CapEx'!H30 | I17: =-'Debt & CapEx'!I30 | J17: =-'Debt & CapEx'!J30 | K17: =-'Debt & CapEx'!K30 | L17: =-'Debt & CapEx'!L30
A18: Other Investing Activities | B18: RMB mn
A20: Cash from Investing | B20: RMB mn | H20: =H17+H18 | I20: =I17+I18 | J20: =J17+J18 | K20: =K17+K18 | L20: =L17+L18
A22: FINANCING ACTIVITIES
A23: Debt Drawdown | B23: RMB mn | H23: ='Debt & CapEx'!H24 | I23: ='Debt & CapEx'!I24 | J23: ='Debt & CapEx'!J24 | K23: ='Debt & CapEx'!K24 | L23: ='Debt & CapEx'!L24
A24: Debt Repayment | B24: RMB mn | H24: =-'Debt & CapEx'!H25 | I24: =-'Debt & CapEx'!I25 | J24: =-'Debt & CapEx'!J25 | K24: =-'Debt & CapEx'!K25 | L24: =-'Debt & CapEx'!L25
A25: Dividends Paid | B25: RMB mn | H25: =-'Income Statement'!H30*'Key Assumptions'!H67 | I25: =-'Income Statement'!I30*'Key Assumptions'!I67 | J25: =-'Income Statement'!J30*'Key Assumptions'!J67 | K25: =-'Income Statement'!K30*'Key Assumptions'!K67 | L25: =-'Income Statement'!L30*'Key Assumptions'!L67
A26: Equity Issuance / (Buyback) | B26: RMB mn
A28: Cash from Financing | B28: RMB mn | H28: =H23+H24+H25+H26 | I28: =I23+I24+I25+I26 | J28: =J23+J24+J25+J26 | K28: =K23+K24+K25+K26 | L28: =L23+L24+L25+L26
A30: Net Change in Cash | B30: RMB mn | H30: =H14+H20+H28 | I30: =I14+I20+I28 | J30: =J14+J20+J28 | K30: =K14+K20+K28 | L30: =L14+L20+L28
A31: Beginning Cash | B31: RMB mn | H31: =G32 | I31: =H32 | J31: =I32 | K31: =J32 | L31: =K32
A32: Ending Cash | B32: RMB mn | H32: =H31+H30 | I32: =I31+I30 | J32: =J31+J30 | K32: =K31+K30 | L32: =L31+L30
A34: Cash Tie-out (must = 0) | B34: RMB mn | H34: =ROUND(H32-'Balance Sheet'!H6,2) | I34: =ROUND(I32-'Balance Sheet'!I6,2) | J34: =ROUND(J32-'Balance Sheet'!J6,2) | K34: =ROUND(K32-'Balance Sheet'!K6,2) | L34: =ROUND(L32-'Balance Sheet'!L6,2)

Sheet Working Capital
A1: Working Capital
D3: 2021 | E3: 2022 | F3: 2023 | G3: 2024 | H3: 2025E | I3: 2026E | J3: 2027E | K3: 2028E | L3: 2029E
A5: WORKING CAPITAL DAYS
A6: Accounts Receivable Days | B6: days
A7: Inventory Days | B7: days
A8: Accounts Payable Days | B8: days
A10: WORKING CAPITAL BALANCES
A11: Accounts Receivable | B11: RMB mn | H11: ='Key Assumptions'!H34/365*H6 | I11: ='Key Assumptions'!I34/365*I6 | J11: ='Key Assumptions'!J34/365*J6 | K11: ='Key Assumptions'!K34/365*K6 | L11: ='Key Assumptions'!L34/365*L6
A12: Inventory | B12: RMB mn | H12: ='COGS & OpEx'!H10/365*H7 | I12: ='COGS & OpEx'!I10/365*I7 | J12: ='COGS & OpEx'!J10/365*J7 | K12: ='COGS & OpEx'!K10/365*K7 | L12: ='COGS & OpEx'!L10/365*L7
A13: Accounts Payable | B13: RMB mn | H13: ='COGS & OpEx'!H10/365*H8 | I13: ='COGS & OpEx'!I10/365*I8 | J13: ='COGS & OpEx'!J10/365*J8 | K13: ='COGS & OpEx'!K10/365*K8 | L13: ='COGS & OpEx'!L10/365*L8
A15: Net Working Capital | B15: RMB mn | H15: =H11+H12-H13 | I15: =I11+I12-I13 | J15: =J11+J12-J13 | K15: =K11+K12-K13 | L15: =L11+L12-L13
A17: CHANGES IN WORKING CAPITAL
A18: Change in AR | B18: RMB mn | H18: =H11-G11 | I18: =I11-H11 | J18: =J11-I11 | K18: =K11-J11 | L18: =L11-K11
A19: Change in Inventory | B19: RMB mn | H19: =H12-G12 | I19: =I12-H12 | J19: =J12-I12 | K19: =K12-J12 | L19: =L12-K12
A20: Change in AP | B20: RMB mn | H20: =H13-G13 | I20: =I13-H13 | J20: =J13-I13 | K20: =K13-J13 | L20: =L13-K13
A22: Change in Net Working Capital | B22: RMB mn | H22: =H15-G15 | I22: =I15-H15 | J22: =J15-I15 | K22: =K15-J15 | L22: =L15-K15

Sheet Debt & CapEx
A1: Debt & CapEx
D3: 2021 | E3: 2022 | F3: 2023 | G3: 2024 | H3: 2025E | I3: 2026E | J3: 2027E | K3: 2028E | L3: 2029E
A5: DEBT TRANCHE 1
A6: Beginning Balance | B6: RMB mn | H6: =G9 | I6: =H9 | J6: =I9 | K6: =J9 | L6: =K9
A7: Drawdown | B7: RMB mn
A8: Repayment | B8: RMB mn
A9: Ending Balance | B9: RMB mn | H9: =H6+H7-H8 | I9: =I6+I7-I8 | J9: =J6+J7-J8 | K9: =K6+K7-K8 | L9: =L6+L7-L8
A10: Interest Rate | B10: %
A11: Interest Expense | B11: RMB mn | H11: =H9*H10 | I11: =I9*I10 | J11: =J9*J10 | K11: =K9*K10 | L11: =L9*L10
A13: DEBT TRANCHE 2
A14: Beginning Balance | B14: RMB mn | H14: =G17 | I14: =H17 | J14: =I17 | K14: =J17 | L14: =K17
A15: Drawdown | B15: RMB mn
A16: Repayment | B16: RMB mn
A17: Ending Balance | B17: RMB mn | H17: =H14+H15-H16 | I17: =I14+I15-I16 | J17: =J14+J15-J16 | K17: =K14+K15-K16 | L17: =L14+L15-L16
A18: Interest Rate | B18: %
A19: Interest Expense | B19: RMB mn | H19: =H17*H18 | I19: =I17*I18 | J19: =J17*J18 | K19: =K17*K18 | L19: =L17*L18
A21: DEBT SUMMARY
A22: Total Debt Outstanding | B22: RMB mn | H22: =H9+H17 | I22: =I9+I17 | J22: =J9+J17 | K22: =K9+K17 | L22: =L9+L17
A23: Total Interest Expense | B23: RMB mn | H23: =H11+H19 | I23: =I11+I19 | J23: =J11+J19 | K23: =K11+K19 | L23: =L11+L19
A24: Total Drawdown | B24: RMB mn | H24: =H7+H15 | I24: =I7+I15 | J24: =J7+J15 | K24: =K7+K15 | L24: =L7+L15
A25: Total Repayment | B25: RMB mn | H25: =H8+H16 | I25: =I8+I16 | J25: =J8+J16 | K25: =K8+K16 | L25: =L8+L16
A27: CAPITAL EXPENDITURES
A28: Maintenance CapEx | B28: RMB mn
A29: Growth CapEx | B29: RMB mn
A30: Total CapEx | B30: RMB mn | H30: =H28+H29 | I30: =I28+I29 | J30: =J28+J29 | K30: =K28+K29 | L30: =L28+L29
A32: PP&E ROLL-FORWARD
A33: Beginning PP&E | B33: RMB mn | H33: =G36 | I33: =H36 | J33: =I36 | K33: =J36 | L33: =K36
A34: (+) CapEx | B34: RMB mn | H34: =H30 | I34: =I30 | J34: =J30 | K34: =K30 | L34: =L30
A35: (-) Depreciation | B35: RMB mn | H35: =H33*'Key Assumptions'!H54 | I35: =I33*'Key Assumptions'!I54 | J35: =J33*'Key Assumptions'!J54 | K35: =K33*'Key Assumptions'!K54 | L35: =L33*'Key Assumptions'!L54
A36: Ending PP&E | B36: RMB mn | H36: =H33+H34-H35 | I36: =I33+I34-I35 | J36: =J33+J34-J35 | K36: =K33+K34-K35 | L36: =L33+L34-L35

Sheet Returns & Sensitivity
A1: Returns & Sensitivity
D3: 2021 | E3: 2022 | F3: 2023 | G3: 2024 | H3: 2025E | I3: 2026E | J3: 2027E | K3: 2028E | L3: 2029E
A5: ENTRY ASSUMPTIONS
A6: Entry Revenue | B6: RMB mn
A7: Entry Net Income | B7: RMB mn
A8: Entry P/S Multiple | B8: x
A9: Entry P/E Multiple | B9: x
A10: Entry Enterprise Value | B10: RMB mn
A11: Entry Net Debt | B11: RMB mn
A12: Entry Equity Value | B12: RMB mn
A14: EXIT — P/S METHOD
A15: Exit Year Revenue | B15: RMB mn
A16: Exit P/S Multiple | B16: x
A17: Exit Enterprise Value | B17: RMB mn | H17: =H15*H16 | I17: =I15*I16 | J17: =J15*J16 | K17: =K15*K16 | L17: =L15*L16
A18: Exit Net Debt | B18: RMB mn
A19: Exit Equity Value | B19: RMB mn | H19: =H17-H18 | I19: =I17-I18 | J19: =J17-J18 | K19: =K17-K18 | L19: =L17-L18
A20: MOIC (P/S) | B20: x | H20: =IF(H12=0,"",H19/H12) | I20: =IF(I12=0,"",I19/I12) | J20: =IF(J12=0,"",J19/J12) | K20: =IF(K12=0,"",K19/K12) | L20: =IF(L12=0,"",L19/L12)
A21: IRR (P/S) | B21: %
A23: EXIT — P/E METHOD
A24: Exit Year Net Income | B24: RMB mn
A25: Exit P/E Multiple | B25: x
A26: Exit Equity Value | B26: RMB mn | H26: =H24*H25 | I26: =I24*I25 | J26: =J24*J25 | K26: =K24*K25 | L26: =L24*L25
A27: MOIC (P/E) | B27: x | H27: =IF(H12=0,"",H26/H12) | I27: =IF(I12=0,"",I26/I12) | J27: =IF(J12=0,"",J26/J12) | K27: =IF(K12=0,"",K26/K12) | L27: =IF(L12=0,"",L26/L12)
A28: IRR (P/E) | B28: %
A31: SENSITIVITY: IRR vs ENTRY x EXIT P/E
A43: SENSITIVITY: MOIC vs REV CAGR x EXIT YEAR

Sheet DCF Valuation
A1: DCF Valuation
D3: 2021 | E3: 2022 | F3: 2023 | G3: 2024 | H3: 2025E | I3: 2026E | J3: 2027E | K3: 2028E | L3: 2029E
A5: WACC CALCULATION
A6: Risk-Free Rate | B6: %
A7: Beta | B7: x
A8: Market Risk Premium | B8: %
A9: Cost of Equity | B9: % | H9: =H6+H7*H8
A10: Pre-tax Cost of Debt | B10: %
A11: Tax Rate | B11: %
A12: Equity Weight (E/V) | B12: %
A13: Debt Weight (D/V) | B13: %
A14: WACC | B14: % | H14: =H12*H9+H13*H10*(1-H11)
A16: UNLEVERED FREE CASH FLOW
A17: EBIT | B17: RMB mn | H17: ='Income Statement'!H20 | I17: ='Income Statement'!I20 | J17: ='Income Statement'!J20 | K17: ='Income Statement'!K20 | L17: ='Income Statement'!L20
A18: Tax on EBIT | B18: RMB mn | H18: =H17*H11 | I18: =I17*H11 | J18: =J17*H11 | K18: =K17*H11 | L18: =L17*H11
A19: NOPAT | B19: RMB mn | H19: =H17-H18 | I19: =I17-I18 | J19: =J17-J18 | K19: =K17-K18 | L19: =L17-L18
A20: (+) D&A | B20: RMB mn | H20: ='COGS & OpEx'!H29 | I20: ='COGS & OpEx'!I29 | J20: ='COGS & OpEx'!J29 | K20: ='COGS & OpEx'!K29 | L20: ='COGS & OpEx'!L29
A21: (-) CapEx | B21: RMB mn | H21: ='Debt & CapEx'!H30 | I21: ='Debt & CapEx'!I30 | J21: ='Debt & CapEx'!J30 | K21: ='Debt & CapEx'!K30 | L21: ='Debt & CapEx'!L30
A22: (-) Change in WC | B22: RMB mn | H22: ='Working Capital'!H22 | I22: ='Working Capital'!I22 | J22: ='Working Capital'!J22 | K22: ='Working Capital'!K22 | L22: ='Working Capital'!L22
A24: Unlevered FCF | B24: RMB mn | H24: =H19+H20-H21-H22 | I24: =I19+I20-I21-I22 | J24: =J19+J20-J21-J22 | K24: =K19+K20-K21-K22 | L24: =L19+L20-L21-L22
A26: DISCOUNT FACTORS
A27: Discount Period (mid-year) | H27: 0.5 | I27: 1.5 | J27: 2.5 | K27: 3.5 | L27: 4.5
A28: Discount Factor | H28: =1/(1+$H$14)^H27 | I28: =1/(1+$H$14)^I27 | J28: =1/(1+$H$14)^J27 | K28: =1/(1+$H$14)^K27 | L28: =1/(1+$H$14)^L27
A29: PV of FCF | B29: RMB mn | H29: =H24*H28 | I29: =I24*I28 | J29: =J24*J28 | K29: =K24*K28 | L29: =L24*L28
A31: TERMINAL VALUE
A32: TV Method
A33: Terminal Growth Rate | B33: %
A34: Exit EV/EBITDA Multiple | B34: x
A35: Terminal Value | B35: RMB mn
A36: PV of Terminal Value | B36: RMB mn
A38: ENTERPRISE & EQUITY VALUE
A39: Sum of PV(FCF) | B39: RMB mn
A40: Enterprise Value | B40: RMB mn
A41: Net Debt | B41: RMB mn
A42: Equity Value | B42: RMB mn

Sheet Comps
A1: Comps
A3: COMPARABLE COMPANIES
A4: Comp 1 | B4: RMB mn
A5: Comp 2 | B5: RMB mn
A6: Comp 3 | B6: RMB mn
A7: Comp 4 | B7: RMB mn
A8: Comp 5 | B8: RMB mn
A9: Comp 6 | B9: RMB mn
A10: Comp 7 | B10: RMB mn
A11: Comp 8 | B11: RMB mn
A12: Comp 9 | B12: RMB mn
A13: Comp 10 | B13: RMB mn
A14: Comp 11 | B14: RMB mn
A15: Comp 12 | B15: RMB mn
A17: Mean
A18: Median
A19: 25th Percentile
A20: 75th Percentile
A22: IMPLIED VALUATION
A23: Target Revenue (NTM) | B23: RMB mn
A24: Target EBITDA (NTM) | B24: RMB mn
A25: Target EBIT (NTM) | B25: RMB mn
A26: Target Net Income (NTM) | B26: RMB mn
A27: Implied EV (EV/Revenue) | B27: RMB mn
A28: Implied EV (EV/EBITDA) | B28: RMB mn
A29: Implied EV (EV/EBIT) | B29: RMB mn
A30: Implied Equity (P/E) | B30: RMB mn

Sheet Dashboard
A1: Dashboard
A3: KEY PERFORMANCE INDICATORS
A4: Revenue | B4: RMB mn
A5: EBITDA | B5: RMB mn
A6: EBITDA Margin | B6: %
A7: Net Income | B7: RMB mn
A8: Net Margin | B8: %
A9: Revenue CAGR (5yr) | B9: %
A11: RETURNS SUMMARY
A12: IRR (P/S Method) | B12: %
A13: MOIC (P/S Method) | B13: x
A14: IRR (P/E Method) | B14: %
A15: MOIC (P/E Method) | B15: x
A17: MODEL INTEGRITY CHECKS
A18: Balance Sheet Check
A19: Cash Tie-out Check
A21: KEY METRICS BY YEAR
A23: Revenue | B23: RMB mn
A24: EBITDA | B24: RMB mn
A25: Net Income | B25: RMB mn
A26: Free Cash Flow | B26: RMB mn
